Workbook

Sheet Assumptions
B2: CHARTER CATAMARAN FINANCIAL MODEL
B3: Caribbean Charter — No-BS Numbers
B5: PURCHASE & FINANCING
B6: Boat Purchase Price | C6: 700000 | D6: New Lagoon 46 / Bali 4.6 range
B7: Down Payment % | C7: 0.2 | D7: Most marine lenders require 15-20%
B8: Down Payment ($) | C8: =C6*C7 -> 140000
B9: Loan Amount | C9: =C6-C8 -> 560000
B10: Loan Term (years) | C10: 20 | D10: 15-20 typical for marine
B11: Interest Rate (APR) | C11: 0.0825 | D11: Current marine rates ~7.5-9%
B12: Monthly Payment | C12: =-PMT(C11/12, C10*12, C9) -> 4771.5677
B13: Annual Debt Service | C13: =C12*12 -> 57258.812
B15: CHARTER REVENUE ASSUMPTIONS
C16: Conservative | D16: Moderate | E16: Optimistic | F16: Notes
B17: Charter Weeks Available/Year | C17: 36 | D17: 40 | E17: 44 | F17: After your personal use + maintenance
B18: Booking Occupancy Rate | C18: 0.55 | D18: 0.7 | E18: 0.82 | F18: Caribbean avg ~60-75%. Year 1 usually lower
B19: Weeks Actually Booked | C19: =C17*C18 -> 19.8 | D19: =D17*D18 -> 28 | E19: =E17*E18 -> 36.08
B20: Avg Weekly Charter Rate | C20: 4200 | D20: 5000 | E20: 5800 | F20: Bareboat 45-50ft cat, Caribbean high season mix
B21: Gross Charter Revenue | C21: =C19*C20 -> 83160 | D21: =D19*D20 -> 140000 | E21: =E19*E20 -> 209264
B23: ANNUAL OPERATING EXPENSES
C24: Conservative | D24: Moderate | E24: Optimistic | F24: Notes
B25: Charter Mgmt Co. Cut (% of gross) | C25: 0.3 | D25: 0.25 | E25: 0.2 | F25: Moorings/DYC ~25-35%. Negotiate hard.
B26: Charter Mgmt Fee ($) | C26: =C21*C25 -> 24948 | D26: =D21*D25 -> 35000 | E26: =E21*E25 -> 41852.8
B27: Insurance (hull + liability) | C27: 14000 | D27: 12000 | E27: 10000 | F27: Caribbean = higher premiums, hurricane zone
B28: Maintenance Reserve (% of boat value) | C28: 0.03 | D28: 0.025 | E28: 0.02 | F28: Industry rule: 2-4% of value/year
B29: Maintenance Reserve ($) | C29: =Assumptions!C6*C28 -> 21000 | D29: =Assumptions!C6*D28 -> 17500 | E29: =Assumptions!C6*E28 -> 14000
B30: Slip/Marina Fees | C30: 9600 | D30: 7200 | E30: 6000 | F30: Home base when not chartered
B31: Haul-Out & Bottom Paint | C31: 6000 | D31: 5000 | E31: 4000 | F31: Annual in Caribbean (growth is aggressive)
B32: Provisioning/Turnover Costs | C32: 4800 | D32: 3600 | E32: 2400 | F32: $100-150/turnover × bookings
B33: Miscellaneous/Contingency | C33: 5000 | D33: 3500 | E33: 2000 | F33: Things WILL break. Budget for it.
B34: Total Operating Expenses | C34: =SUM(C26,C27,C29,C30,C31,C32,C33) -> 85348 | D34: =SUM(D26,D27,D29,D30,D31,D32,D33) -> 83800 | E34: =SUM(E26,E27,E29,E30,E31,E32,E33) -> 80252.8

Sheet Partnership Split
B2: PARTNERSHIP ECONOMICS — WHO MAKES WHAT
B3: Used boat scenario with captain-partner in charter fleet
B5: DEAL STRUCTURE
B6: Used Boat Purchase Price | C6: 500000 | F6: Sweet spot: 3-5yr old cat
B7: Down Payment % (each partner) | C7: 0.1 | F7: 10% each = 20% total
B8: Your Down Payment | C8: =C6*C7 -> 50000
B9: Partner's Down Payment | C9: =C6*C7 -> 50000
B10: Total Down Payment | C10: =C8+C9 -> 100000
B11: Loan Amount | C11: =C6-C10 -> 400000
B12: Loan Term (years) | C12: 15 | F12: Shorter term typical on used
B13: Interest Rate | C13: 0.0875 | F13: Used = slightly higher rate
B14: Monthly Loan Payment | C14: =-PMT(C13/12,C12*12,C11) -> 3997.7946
B15: Your Monthly Loan Share (50%) | C15: =C14*0.5 -> 1998.8973
B16: Partner's Monthly Loan Share (50%) | C16: =C14*0.5 -> 1998.8973
B17: Ownership Split — You | C17: 0.5
B18: Ownership Split — Partner | C18: 0.5
B20: CHARTER REVENUE — FLEET MANAGED, CREWED
C21: Conservative | D21: Moderate | E21: Optimistic | F21: Notes
B22: Charter Weeks Available/Year | C22: 36 | D22: 40 | E22: 44 | F22: After personal use + maintenance
B23: Booking Occupancy Rate | C23: 0.5 | D23: 0.65 | E23: 0.78 | F23: Crewed can book higher but yr1 is rough
B24: Weeks Actually Booked | C24: =C22*C23 -> 18 | D24: =D22*D23 -> 26 | E24: =E22*E23 -> 34.32
B25: Avg Weekly Rate (Crewed) | C25: 7500 | D25: 9000 | E25: 11000 | F25: Captain-only crewed, 45-50ft Caribbean
B26: Gross Charter Revenue | C26: =C24*C25 -> 135000 | D26: =D24*D25 -> 234000 | E26: =E24*E25 -> 377520
B28: OPERATING EXPENSES
C29: Conservative | D29: Moderate | E29: Optimistic | F29: Notes
B30: Fleet Mgmt Co. Cut (% of gross) | C30: 0.28 | D30: 0.22 | E30: 0.18 | F30: Lower cut when you provide captain
B31: Fleet Mgmt Fee ($) | C31: =C26*C30 -> 37800 | D31: =D26*D30 -> 51480 | E31: =E26*E30 -> 67953.6
B32: Partner Captain Pay (per booked week) | C32: 1200 | D32: 1200 | E32: 1200 | F32: His labor comp, off the top
B33: Total Captain Pay/Year | C33: =C24*C32 -> 21600 | D33: =D24*D32 -> 31200 | E33: =E24*E32 -> 41184
B34: Insurance | C34: 12000 | D34: 10000 | E34: 8500 | F34: Used boat = slightly lower hull value
B35: Maintenance Reserve (% of value) | C35: 0.035 | D35: 0.03 | E35: 0.025 | F35: Higher for used + charter wear
B36: Maintenance Reserve ($) | C36: =C6*C35 -> 17500 | D36: =C6*D35 -> 15000 | E36: =C6*E35 -> 12500
B37: Slip/Marina Fees | C37: 9600 | D37: 7200 | E37: 6000
B38: Haul-Out & Bottom Paint | C38: 6000 | D38: 5000 | E38: 4000
B39: Provisioning/Turnover | C39: 4800 | D39: 3600 | E39: 2400
B40: Miscellaneous | C40: 5000 | D40: 3500 | E40: 2000
B41: Total Operating Expenses | C41: =SUM(C31,C33,C34,C36,C37,C38,C39,C40) -> 114300 | D41: =SUM(D31,D33,D34,D36,D37,D38,D39,D40) -> 126980 | E41: =SUM(E31,E33,E34,E36,E37,E38,E39,E40) -> 144537.6
B43: WHAT EACH PERSON TAKES HOME
C44: Conservative | D44: Moderate | E44: Optimistic
B45: Gross Charter Revenue | C45: =C26 -> 135000 | D45: =D26 -> 234000 | E45: =E26 -> 377520
...

Sheet P&L Summary
B2: ANNUAL CASH FLOW SUMMARY
C3: Conservative | D3: Moderate | E3: Optimistic
B4: Gross Charter Revenue | C4: =Assumptions!C21 -> 83160 | D4: =Assumptions!D21 -> 140000 | E4: =Assumptions!E21 -> 209264
B5: Less: Mgmt Company Fee | C5: =-Assumptions!C26 -> -24948 | D5: =-Assumptions!D26 -> -35000 | E5: =-Assumptions!E26 -> -41852.8
B6: Net Charter Revenue | C6: =C4+C5 -> 58212 | D6: =D4+D5 -> 105000 | E6: =E4+E5 -> 167411.2
B8: Less: Insurance | C8: =-Assumptions!C27 -> -14000 | D8: =-Assumptions!D27 -> -12000 | E8: =-Assumptions!E27 -> -10000
B9: Less: Maintenance Reserve | C9: =-Assumptions!C29 -> -21000 | D9: =-Assumptions!D29 -> -17500 | E9: =-Assumptions!E29 -> -14000
B10: Less: Slip/Marina Fees | C10: =-Assumptions!C30 -> -9600 | D10: =-Assumptions!D30 -> -7200 | E10: =-Assumptions!E30 -> -6000
B11: Less: Haul-Out & Bottom Paint | C11: =-Assumptions!C31 -> -6000 | D11: =-Assumptions!D31 -> -5000 | E11: =-Assumptions!E31 -> -4000
B12: Less: Provisioning/Turnover | C12: =-Assumptions!C32 -> -4800 | D12: =-Assumptions!D32 -> -3600 | E12: =-Assumptions!E32 -> -2400
B13: Less: Miscellaneous | C13: =-Assumptions!C33 -> -5000 | D13: =-Assumptions!D33 -> -3500 | E13: =-Assumptions!E33 -> -2000
B14: Net Operating Income (NOI) | C14: =C6+SUM(C8:C13) -> -2188 | D14: =D6+SUM(D8:D13) -> 56200 | E14: =E6+SUM(E8:E13) -> 129011.2
B16: Less: Annual Debt Service | C16: =-Assumptions!C13 -> -57258.812 | D16: =-Assumptions!C13 -> -57258.812 | E16: =-Assumptions!C13 -> -57258.812
B17: ANNUAL CASH FLOW | C17: =C14+C16 -> -59446.812 | D17: =D14+D16 -> -1058.8118 | E17: =E14+E16 -> 71752.388
B18: Monthly Cash Flow | C18: =C17/12 -> -4953.901 | D18: =D17/12 -> -88.23432 | E18: =E17/12 -> 5979.3657
B20: YOUR PERSONAL USE WEEKS
B21: Charter Weeks Available | C21: =Assumptions!C17 -> 36 | D21: =Assumptions!D17 -> 40 | E21: =Assumptions!E17 -> 44
B22: Personal Use Weeks | C22: =52-C21 -> 16 | D22: =52-D21 -> 12 | E22: =52-E21 -> 8
B23: Effective Cost Per Personal Week | C23: =IF(C22=0,0,-C17/C22) -> 3715.4257 | D23: =IF(D22=0,0,-D17/D22) -> 88.23432 | E23: =IF(E22=0,0,-E17/E22) -> -8969.0485

Sheet 10-Year Projection
B2: 10-YEAR PROJECTION (MODERATE SCENARIO)
B4: Annual Rate Increase | C4: 0.03 | D4: Charter rate growth/yr
B5: Annual Expense Inflation | C5: 0.035 | D5: Expenses grow faster than revenue
B6: Annual Depreciation Rate | C6: 0.04 | D6: Cats hold better than mono, but still depreciates
C8: Year 1 | D8: Year 2 | E8: Year 3 | F8: Year 4 | G8: Year 5 | H8: Year 6 | I8: Year 7 | J8: Year 8 | K8: Year 9 | L8: Year 10
B9: Gross Charter Revenue | C9: =Assumptions!D21 -> 140000 | D9: =C9*(1+$C$4) -> 144200 | E9: =D9*(1+$C$4) -> 148526 | F9: =E9*(1+$C$4) -> 152981.78 | G9: =F9*(1+$C$4) -> 157571.23 | H9: =G9*(1+$C$4) -> 162298.37 | I9: =H9*(1+$C$4) -> 167167.32 | J9: =I9*(1+$C$4) -> 172182.34 | K9: =J9*(1+$C$4) -> 177347.81 | L9: =K9*(1+$C$4) -> 182668.25
B10: Total Operating Expenses | C10: =Assumptions!D34 -> 83800 | D10: =C10*(1+$C$5) -> 86733 | E10: =D10*(1+$C$5) -> 89768.655 | F10: =E10*(1+$C$5) -> 92910.558 | G10: =F10*(1+$C$5) -> 96162.427 | H10: =G10*(1+$C$5) -> 99528.112 | I10: =H10*(1+$C$5) -> 103011.6 | J10: =I10*(1+$C$5) -> 106617 | K10: =J10*(1+$C$5) -> 110348.6 | L10: =K10*(1+$C$5) -> 114210.8
B11: Net Operating Income | C11: =C9-C10 -> 56200 | D11: =D9-D10 -> 57467 | E11: =E9-E10 -> 58757.345 | F11: =F9-F10 -> 60071.222 | G11: =G9-G10 -> 61408.806 | H11: =H9-H10 -> 62770.258 | I11: =I9-I10 -> 64155.725 | J11: =J9-J10 -> 65565.339 | ... L11: =L9-L10 -> 68457.448
B12: Debt Service | C12: =Assumptions!C13 -> 57258.812 | D12: =Assumptions!C13 -> 57258.812 | E12: =Assumptions!C13 -> 57258.812 | F12: =Assumptions!C13 -> 57258.812 | G12: =Assumptions!C13 -> 57258.812 | H12: =Assumptions!C13 -> 57258.812 | I12: =Assumptions!C13 -> 57258.812 | J12: =Assumptions!C13 -> 57258.812 | K12: =Assumptions!C13 -> 57258.812 | L12: =Assumptions!C13 -> 57258.812
B13: Annual Cash Flow | C13: =C11-C12 -> -1058.8118 | D13: =D11-D12 -> 208.18816 | E13: =E11-E12 -> 1498.5332 | F13: =F11-F12 -> 2812.4102 | G13: =G11-G12 -> 4149.9941 | H13: =H11-H12 -> 5511.4462 | I13: =I11-I12 -> 6896.9133 | J13: =J11-J12 -> 8306.5271 | ... L13: =L11-L12 -> 11198.636
B15: Cumulative Cash Flow | C15: =C13 -> -1058.8118 | D15: =C15+D13 -> -850.62367 | E15: =D15+E13 -> 647.90949 | F15: =E15+F13 -> 3460.3197 | G15: =F15+G13 -> 7610.3138 | H15: =G15+H13 -> 13121.76 | I15: =H15+I13 -> 20018.673 | J15: =I15+J13 -> 28325.2 | K15: =J15+K13 -> 38065.603 | L15: =K15+L13 -> 49264.238
B16: Boat Market Value | C16: =Assumptions!C6*(1-$C$6) -> 672000 | D16: =C16*(1-$C$6) -> 645120 | E16: =D16*(1-$C$6) -> 619315.2 | F16: =E16*(1-$C$6) -> 594542.59 | G16: =F16*(1-$C$6) -> 570760.89 | H16: =G16*(1-$C$6) -> 547930.45 | I16: =H16*(1-$C$6) -> 526013.23 | J16: =I16*(1-$C$6) -> 504972.71 | K16: =J16*(1-$C$6) -> 484773.8 | L16: =K16*(1-$C$6) -> 465382.85
B17: Remaining Loan Balance | C17: =IF(Assumptions!C9>0, PV(Assumptions!C11/12, (Assumptions!C10-1)*12, -Assumptions!C12), 0) -> 548513.29 | D17: =IF(Assumptions!C9>0, PV(Assumptions!C11/12, (Assumptions!C10-2)*12, -Assumptions!C12), 0) -> 536042.27 | E17: =IF(Assumptions!C9>0, PV(Assumptions!C11/12, (Assumptions!C10-3)*12, -Assumptions!C12), 0) -> 522502.57 | F17: =IF(Assumptions!C9>0, PV(Assumptions!C11/12, (Assumptions!C10-4)*12, -Assumptions!C12), 0) -> 507802.63 | G17: =IF(Assumptions!C9>0, PV(Assumptions!C11/12, (Assumptions!C10-5)*12, -Assumptions!C12), 0) -> 491843.02 | H17: =IF(Assumptions!C9>0, PV(Assumptions!C11/12, (Assumptions!C10-6)*12, -Assumptions!C12), 0) -> 474515.8 | I17: =IF(Assumptions!C9>0, PV(Assumptions!C11/12, (Assumptions!C10-7)*12, -Assumptions!C12), 0) -> 455703.77 | J17: =IF(Assumptions!C9>0, PV(Assumptions!C11/12, (Assumptions!C10-8)*12, -Assumptions!C12), 0) -> 435279.7 | K17: =IF(Assumptions!C9>0, PV(Assumptions!C11/12, (Assumptions!C10-9)*12, -Assumptions!C12), 0) -> 413105.44 | L17: =IF(Assumptions!C9>0, PV(Assumptions!C11/12, (Assumptions!C10-10)*12, -Assumptions!C12), 0) -> 389031.03
B18: Equity Position | C18: =C16-C17 -> 123486.71 | D18: =D16-D17 -> 109077.73 | E18: =E16-E17 -> 96812.627 | F18: =F16-F17 -> 86739.96 | G18: =G16-G17 -> 78917.866 | H18: =H16-H17 -> 73414.654 | I18: =I16-I17 -> 70309.466 | J18: =J16-J17 -> 69693.009 | ... L18: =L16-L17 -> 76351.82
B20: Total Return (Equity + Cum CF) | C20: =C18+C15 -> 122427.89 | D20: =D18+D15 -> 108227.11 | E20: =E18+E15 -> 97460.537 | F20: =F18+F15 -> 90200.28 | G20: =G18+G15 -> 86528.18 | H20: =H18+H15 -> 86536.414 | I20: =I18+I15 -> 90328.139 | J20: =J18+J15 -> 98018.21 | ... L20: =L18+L15 -> 125616.06
B21: vs. Down Payment Invested | C21: =C20-Assumptions!C8 -> -17572.106 | D21: =D20-Assumptions!C8 -> -31772.891 | E21: =E20-Assumptions!C8 -> -42539.463 | F21: =F20-Assumptions!C8 -> -49799.72 | G21: =G20-Assumptions!C8 -> -53471.82 | H21: =H20-Assumptions!C8 -> -53463.586 | I21: =I20-Assumptions!C8 -> -49671.861 | J21: =J20-Assumptions!C8 -> -41981.79 | K21: =K20-Assumptions!C8 -> -30266.041 | L21: =L20-Assumptions!C8 -> -14383.942

Sheet Reality Check
B2: REALITY CHECK — THINGS THE BROCHURE WON'T TELL YOU
B4: HURRICANE RISK
B5: Caribbean season is June-November. Insurance deductibles are typically 2-5% of hull value ($14K-$35K on a $700K boat). Named storm exclusions are common. Budget $2-5K/yr for hurricane haul-out or relocation.
B7: YEAR 1 IS THE WORST
B8: Commissioning delays, shakedown issues, building charter reviews from zero. Budget for 40-50% occupancy year 1, not 70%.
B10: CHARTER WEAR IS REAL
B11: Charter guests are NOT gentle. Winches, sails, trampolines, engines see 3-5x the wear of private use. Budget maintenance accordingly.
B13: MANAGEMENT CO. INCENTIVES
B14: Their fee is based on gross revenue, not your profit. They're incentivized to book volume, not protect your boat. Inspect often.
B16: THE EXIT
B17: When you sell, a boat with 8-10 years of charter use sells for LESS than a private-use equivalent. Factor 10-20% additional discount vs. market.
B19: TAX COMPLEXITY
... B26: Your $140K down payment in the S&P 500 at 10% avg return = ~$363K in 10 years. The boat needs to beat that to be a purely financial win. Most people do this for lifestyle + partial offset, not pure ROI.

Sheet Stress Test
B2: STRESS TEST — HOW BAD CAN IT GET?
B3: Monthly burn at various occupancy levels (used boat, partnership)
C5: 20% Occ | D5: 30% Occ | E5: 40% Occ | F5: 50% Occ | G5: 60% Occ | H5: 70% Occ | I5: 80% Occ
B6: Weeks Booked (of 40 avail) | C6: =40*0.2 -> 8 | D6: =40*0.3 -> 12 | E6: =40*0.4 -> 16 | F6: =40*0.5 -> 20 | G6: =40*0.6 -> 24 | H6: =40*0.7 -> 28 | I6: =40*0.8 -> 32
B7: Gross Revenue | C7: =C6*9000 -> 72000 | D7: =D6*9000 -> 108000 | E7: =E6*9000 -> 144000 | F7: =F6*9000 -> 180000 | G7: =G6*9000 -> 216000 | H7: =H6*9000 -> 252000 | I7: =I6*9000 -> 288000
B8: Fleet Mgmt Fee (22%) | C8: =-C7*0.22 -> -15840 | D8: =-D7*0.22 -> -23760 | E8: =-E7*0.22 -> -31680 | F8: =-F7*0.22 -> -39600 | G8: =-G7*0.22 -> -47520 | H8: =-H7*0.22 -> -55440 | I8: =-I7*0.22 -> -63360
B9: Captain Pay | C9: =-C6*1200 -> -9600 | D9: =-D6*1200 -> -14400 | E9: =-E6*1200 -> -19200 | F9: =-F6*1200 -> -24000 | G9: =-G6*1200 -> -28800 | H9: =-H6*1200 -> -33600 | I9: =-I6*1200 -> -38400
B10: Insurance | C10: -10000 | D10: -10000 | E10: -10000 | F10: -10000 | G10: -10000 | H10: -10000 | I10: -10000
B11: Maintenance | C11: -15000 | D11: -15000 | E11: -15000 | F11: -15000 | G11: -15000 | H11: -15000 | I11: -15000
B12: Slip + Haul + Prov + Misc | C12: -19300 | D12: -19300 | E12: -19300 | F12: -19300 | G12: -19300 | H12: -19300 | I12: -19300
B13: Total Expenses | C13: =SUM(C8:C12) -> -69740 | D13: =SUM(D8:D12) -> -82460 | E13: =SUM(E8:E12) -> -95180 | F13: =SUM(F8:F12) -> -107900 | G13: =SUM(G8:G12) -> -120620 | H13: =SUM(H8:H12) -> -133340 | I13: =SUM(I8:I12) -> -146060
B14: Net Operating Income | C14: =C7+C13 -> 2260 | D14: =D7+D13 -> 25540 | E14: =E7+E13 -> 48820 | F14: =F7+F13 -> 72100 | G14: =G7+G13 -> 95380 | H14: =H7+H13 -> 118660 | I14: =I7+I13 -> 141940
B15: Annual Debt Service | C15: =-'Partnership Split'!C14*12 -> -47973.535 | D15: =-'Partnership Split'!C14*12 -> -47973.535 | E15: =-'Partnership Split'!C14*12 -> -47973.535 | F15: =-'Partnership Split'!C14*12 -> -47973.535 | G15: =-'Partnership Split'!C14*12 -> -47973.535 | H15: =-'Partnership Split'!C14*12 -> -47973.535 | I15: =-'Partnership Split'!C14*12 -> -47973.535
B16: Annual Cash Flow | C16: =C14+C15 -> -45713.535 | D16: =D14+D15 -> -22433.535 | E16: =E14+E15 -> 846.46477 | F16: =F14+F15 -> 24126.465 | G16: =G14+G15 -> 47406.465 | H16: =H14+H15 -> 70686.465 | I16: =I14+I15 -> 93966.465
B18: MONTHLY CASH FLOW (total) | C18: =C16/12 -> -3809.4613 | D18: =D16/12 -> -1869.4613 | E18: =E16/12 -> 70.538731 | F18: =F16/12 -> 2010.5387 | G18: =G16/12 -> 3950.5387 | H18: =H16/12 -> 5890.5387 | I18: =I16/12 -> 7830.5387
B19: Your Monthly Share | C19: =C18*0.5 -> -1904.7306 | D19: =D18*0.5 -> -934.73063 | E19: =E18*0.5 -> 35.269365 | F19: =F18*0.5 -> 1005.2694 | G19: =G18*0.5 -> 1975.2694 | H19: =H18*0.5 -> 2945.2694 | I19: =I18*0.5 -> 3915.2694
B20: Partner's Monthly (captain + share) | C20: =-C9/12+C18*0.5 -> -1104.7306 | D20: =-D9/12+D18*0.5 -> 265.26937 | E20: =-E9/12+E18*0.5 -> 1635.2694 | F20: =-F9/12+F18*0.5 -> 3005.2694 | G20: =-G9/12+G18*0.5 -> 4375.2694 | H20: =-H9/12+H18*0.5 -> 5745.2694 | I20: =-I9/12+I18*0.5 -> 7115.2694
B22: MONTHS OF RESERVES NEEDED | C22: =IF(C18<0, -C18*12, 0) -> 45713.535 | D22: =IF(D18<0, -D18*12, 0) -> 22433.535 | E22: =IF(E18<0, -E18*12, 0) -> 0 | F22: =IF(F18<0, -F18*12, 0) -> 0 | G22: =IF(G18<0, -G18*12, 0) -> 0 | H22: =IF(H18<0, -H18*12, 0) -> 0 | I22: =IF(I18<0, -I18*12, 0) -> 0
B23: (to cover 12mo if this is your actual occupancy)
B24: RED = you are bleeding money. The question is: how much reserve do you need to survive a bad year?
